Workbook

Sheet Schedule
A1: GTS Pickleball 2026 — offline backup (use only if the website is down)
A2: Type scores in the yellow cells. League/semis: points in G1. Finals: up to 3 games. For semis and finals, type the team names in the yellow Team cells (use the Standings tabs for seeds).
A4: Time | B4: Court | C4: Division | D4: Stage | E4: Team A | F4: Team B | G4: G1 A | H4: G1 B | I4: G2 A | J4: G2 B | K4: G3 A | L4: G3 B | M4: Winner | N4: Match ID
A5: 7:00 AM | B5: 1 | C5: Open 3.5 | D5: League | E5: Venkat & Immanuel | F5: Scott & Harshad | M5: =IF(COUNT(G5:H5)<2,"",IF(G5>H5,E5,IF(H5>G5,F5,""))) | N5: o35-L01
A6: 7:00 AM | B6: 2 | C6: Open 3.5 | D6: League | E6: GV Lakshman & Brad Salyers | F6: Shari & Michelle | M6: =IF(COUNT(G6:H6)<2,"",IF(G6>H6,E6,IF(H6>G6,F6,""))) | N6: o35-L02
A7: 7:00 AM | B7: 3 | C7: Open 3.5 | D7: League | E7: Vamsi & Vanith | F7: Thiru & Gitanshu | M7: =IF(COUNT(G7:H7)<2,"",IF(G7>H7,E7,IF(H7>G7,F7,""))) | N7: o35-L03
A8: 7:00 AM | B8: 4 | C8: Open 3.5 | D8: League | E8: Singa & Sekar | F8: Satish & Mahesh | M8: =IF(COUNT(G8:H8)<2,"",IF(G8>H8,E8,IF(H8>G8,F8,""))) | N8: o35-L04
A9: 7:00 AM | B9: 5 | C9: Open 3.0 | D9: League | E9: Karthik Peddireddy & Jaimin Raval | F9: Ramesh & Kelly | M9: =IF(COUNT(G9:H9)<2,"",IF(G9>H9,E9,IF(H9>G9,F9,""))) | N9: o30-L01
A10: 7:00 AM | B10: 6 | C10: Open 3.0 | D10: League | E10: Sreeni & Rajmohan | F10: Cody & Lexy | M10: =IF(COUNT(G10:H10)<2,"",IF(G10>H10,E10,IF(H10>G10,F10,""))) | N10: o30-L02
A11: 7:10 AM | B11: 1 | C11: Open 3.5 | D11: League | E11: Hari & Madhu | F11: Sandeep & Jagan | M11: =IF(COUNT(G11:H11)<2,"",IF(G11>H11,E11,IF(H11>G11,F11,""))) | N11: o35-L05
A12: 7:10 AM | B12: 2 | C12: Open 3.5 | D12: League | E12: Venkat & Immanuel | F12: Shari & Michelle | M12: =IF(COUNT(G12:H12)<2,"",IF(G12>H12,E12,IF(H12>G12,F12,""))) | N12: o35-L06
A13: 7:10 AM | B13: 3 | C13: Open 3.5 | D13: League | E13: Scott & Harshad | F13: Thiru & Gitanshu | M13: =IF(COUNT(G13:H13)<2,"",IF(G13>H13,E13,IF(H13>G13,F13,""))) | N13: o35-L07
A14: 7:10 AM | B14: 4 | C14: Open 3.5 | D14: League | E14: GV Lakshman & Brad Salyers | F14: Satish & Mahesh | M14: =IF(COUNT(G14:H14)<2,"",IF(G14>H14,E14,IF(H14>G14,F14,""))) | N14: o35-L08
A15: 7:10 AM | B15: 5 | C15: Open 3.0 | D15: League | E15: Raja & Praveen | F15: Sunil Rajulapati & Chalapathi Rao | M15: =IF(COUNT(G15:H15)<2,"",IF(G15>H15,E15,IF(H15>G15,F15,""))) | N15: o30-L03
A16: 7:10 AM | B16: 6 | C16: Open 3.0 | D16: League | E16: Karthik Peddireddy & Jaimin Raval | F16: Cody & Lexy | M16: =IF(COUNT(G16:H16)<2,"",IF(G16>H16,E16,IF(H16>G16,F16,""))) | N16: o30-L04
... A36: 7:55 AM | B36: 6 | C36: Open 3.0 | D36: League | E36: Cody & Lexy | F36: Ramesh & Kelly | M36: =IF(COUNT(G36:H36)<2,"",IF(G36>H36,E36,IF(H36>G36,F36,""))) | N36: o30-L12
A37: 8:05 AM | B37: 1 | C37: Open 3.5 | D37: Semi 1 | M37: =IF(COUNT(G37:H37)<2,"",IF(G37>H37,E37,IF(H37>G37,F37,""))) | N37: o35-sf1
A38: 8:05 AM | B38: 2 | C38: Open 3.5 | D38: Semi 2 | M38: =IF(COUNT(G38:H38)<2,"",IF(G38>H38,E38,IF(H38>G38,F38,""))) | N38: o35-sf2
A39: 8:15 AM | B39: 5 | C39: Open 3.0 | D39: Semi 1 | M39: =IF(COUNT(G39:H39)<2,"",IF(G39>H39,E39,IF(H39>G39,F39,""))) | N39: o30-sf1
A40: 8:15 AM | B40: 6 | C40: Open 3.0 | D40: Semi 2 | M40: =IF(COUNT(G40:H40)<2,"",IF(G40>H40,E40,IF(H40>G40,F40,""))) | N40: o30-sf2
A41: 8:30 AM | B41: 1 | C41: Open 3.5 | D41: Final (best of 3) | M41: =IF(COUNT(G41:L41)<4,"",IF((G41>H41)+(I41>J41)+(K41>L41)>=2,E41,IF((H41>G41)+(J41>I41)+(L41>K41)>=2,F41,""))) | N41: o35-final
A42: 8:30 AM | B42: 2 | C42: Mixed Doubles | D42: League | E42: Elango & Ramya | F42: Alexis & Chris | M42: =IF(COUNT(G42:H42)<2,"",IF(G42>H42,E42,IF(H42>G42,F42,""))) | N42: mix-L01
A43: 8:40 AM | B43: 5 | C43: Open 3.0 | D43: Final (best of 3) | M43: =IF(COUNT(G43:L43)<4,"",IF((G43>H43)+(I43>J43)+(K43>L43)>=2,E43,IF((H43>G43)+(J43>I43)+(L43>K43)>=2,F43,""))) | N43: o30-final
A44: 8:55 AM | B44: 1 | C44: Mixed Doubles | D44: League | E44: Elango & Ramya | F44: Dwayne & Shari | M44: =IF(COUNT(G44:H44)<2,"",IF(G44>H44,E44,IF(H44>G44,F44,""))) | N44: mix-L02
A45: 9:00 AM | B45: 6 | C45: Social Doubles | D45: League | E45: Venky & Mohan | F45: Vasikaran & Sudarson | M45: =IF(COUNT(G45:H45)<2,"",IF(G45>H45,E45,IF(H45>G45,F45,""))) | N45: soc-L01
A46: 9:05 AM | B46: 1 | C46: Mixed Doubles | D46: League | E46: Ramesh & Kelly | F46: Tim & Martha | M46: =IF(COUNT(G46:H46)<2,"",IF(G46>H46,E46,IF(H46>G46,F46,""))) | N46: mix-L03
A47: 9:05 AM | B47: 2 | C47: Mixed Doubles | D47: League | E47: Dwayne & Shari | F47: Cody & Lexy | M47: =IF(COUNT(G47:H47)<2,"",IF(G47>H47,E47,IF(H47>G47,F47,""))) | N47: mix-L04
A48: 9:05 AM | B48: 5 | C48: Social Doubles | D48: League | E48: Ramya & Priya | F48: Vanith & Yashna | M48: =IF(COUNT(G48:H48)<2,"",IF(G48>H48,E48,IF(H48>G48,F48,""))) | N48: soc-L02
A49: 9:15 AM | B49: 1 | C49: Mixed Doubles | D49: League | E49: Ramesh & Kelly | F49: Alexis & Chris | M49: =IF(COUNT(G49:H49)<2,"",IF(G49>H49,E49,IF(H49>G49,F49,""))) | N49: mix-L05
A50: 9:15 AM | B50: 2 | C50: Mixed Doubles | D50: League | E50: Tim & Martha | F50: Cody & Lexy | M50: =IF(COUNT(G50:H50)<2,"",IF(G50>H50,E50,IF(H50>G50,F50,""))) | N50: mix-L06
A51: 9:15 AM | B51: 5 | C51: Social Doubles | D51: League | E51: Ramya & Priya | F51: Vasikaran & Sudarson | M51: =IF(COUNT(G51:H51)<2,"",IF(G51>H51,E51,IF(H51>G51,F51,""))) | N51: soc-L03
A52: 9:15 AM | B52: 6 | C52: Social Doubles | D52: League | E52: Vanith & Yashna | F52: Venky & Mohan | M52: =IF(COUNT(G52:H52)<2,"",IF(G52>H52,E52,IF(H52>G52,F52,""))) | N52: soc-L04
A53: 9:25 AM | B53: 1 | C53: Mixed Doubles | D53: League | E53: Alexis & Chris | F53: Dwayne & Shari | M53: =IF(COUNT(G53:H53)<2,"",IF(G53>H53,E53,IF(H53>G53,F53,""))) | N53: mix-L07
A54: 9:30 AM | B54: 2 | C54: Mixed Doubles | D54: League | E54: Ramesh & Kelly | F54: Cody & Lexy | M54: =IF(COUNT(G54:H54)<2,"",IF(G54>H54,E54,IF(H54>G54,F54,""))) | N54: mix-L08
A55: 9:30 AM | B55: 3 | C55: Mixed Doubles | D55: League | E55: Tim & Martha | F55: Elango & Ramya | M55: =IF(COUNT(G55:H55)<2,"",IF(G55>H55,E55,IF(H55>G55,F55,""))) | N55: mix-L09
... A60: 9:50 AM | B60: 5 | C60: Social Doubles | D60: League | E60: Ramya & Priya | F60: Venky & Mohan | M60: =IF(COUNT(G60:H60)<2,"",IF(G60>H60,E60,IF(H60>G60,F60,""))) | N60: soc-L06
A61: 10:00 AM | B61: 1 | C61: Mixed Doubles | D61: Semi 1 | M61: =IF(COUNT(G61:H61)<2,"",IF(G61>H61,E61,IF(H61>G61,F61,""))) | N61: mix-sf1
A62: 10:00 AM | B62: 2 | C62: Mixed Doubles | D62: Semi 2 | M62: =IF(COUNT(G62:H62)<2,"",IF(G62>H62,E62,IF(H62>G62,F62,""))) | N62: mix-sf2
A63: 10:25 AM | B63: 1 | C63: Mixed Doubles | D63: Final (best of 3) | M63: =IF(COUNT(G63:L63)<4,"",IF((G63>H63)+(I63>J63)+(K63>L63)>=2,E63,IF((H63>G63)+(J63>I63)+(L63>K63)>=2,F63,""))) | N63: mix-final
A64: 10:50 AM | B64: 1 | C64: Open 4.0 | D64: League | E64: Vinod & Senthil | F64: Tim & Scott | M64: =IF(COUNT(G64:H64)<2,"",IF(G64>H64,E64,IF(H64>G64,F64,""))) | N64: o40-L01
...

Sheet Open 3.0
A1: Open 3.0 — standings (updates as you type scores on the Schedule tab)
A2: Top 4 go to the semis: 1 v 4 and 2 v 3. Rank: wins, then +/-, then points for.
A4: Team | B4: Played | C4: Won | D4: Lost | E4: Points for | F4: Points against | G4: +/- | H4: Rank
A5: Karthik Peddireddy & Jaimin Raval | B5: =SUMPRODUCT((Schedule!$C$5:$C$83="Open 3.0")*(Schedule!$D$5:$D$83="League")*ISNUMBER(Schedule!$G$5:$G$83)*ISNUMBER(Schedule!$H$5:$H$83)*((Schedule!$E$5:$E$83=A5)+(Schedule!$F$5:$F$83=A5))) -> 0 | C5: =SUMPRODUCT((Schedule!$C$5:$C$83="Open 3.0")*(Schedule!$D$5:$D$83="League")*ISNUMBER(Schedule!$G$5:$G$83)*ISNUMBER(Schedule!$H$5:$H$83)*(((Schedule!$E$5:$E$83=A5)*(Schedule!$G$5:$G$83>Schedule!$H$5:$H$83))+((Schedule!$F$5:$F$83=A5)*(Schedule!$H$5:$H$83>Schedule!$G$5:$G$83)))) -> 0 | D5: =B5-C5 -> 0 | E5: =SUMPRODUCT((Schedule!$C$5:$C$83="Open 3.0")*(Schedule!$D$5:$D$83="League")*ISNUMBER(Schedule!$G$5:$G$83)*ISNUMBER(Schedule!$H$5:$H$83)*(((Schedule!$E$5:$E$83=A5)*Schedule!$G$5:$G$83)+((Schedule!$F$5:$F$83=A5)*Schedule!$H$5:$H$83))) -> 0 | F5: =SUMPRODUCT((Schedule!$C$5:$C$83="Open 3.0")*(Schedule!$D$5:$D$83="League")*ISNUMBER(Schedule!$G$5:$G$83)*ISNUMBER(Schedule!$H$5:$H$83)*(((Schedule!$E$5:$E$83=A5)*Schedule!$H$5:$H$83)+((Schedule!$F$5:$F$83=A5)*Schedule!$G$5:$G$83))) -> 0 | G5: =E5-F5 -> 0 | H5: =RANK(J5,$J$5:$J$10,0) -> 6 | J5: =C5*10000+G5*100+E5+ROW()/1000 -> 0.005
A6: Sreeni & Rajmohan | B6: =SUMPRODUCT((Schedule!$C$5:$C$83="Open 3.0")*(Schedule!$D$5:$D$83="League")*ISNUMBER(Schedule!$G$5:$G$83)*ISNUMBER(Schedule!$H$5:$H$83)*((Schedule!$E$5:$E$83=A6)+(Schedule!$F$5:$F$83=A6))) -> 0 | C6: =SUMPRODUCT((Schedule!$C$5:$C$83="Open 3.0")*(Schedule!$D$5:$D$83="League")*ISNUMBER(Schedule!$G$5:$G$83)*ISNUMBER(Schedule!$H$5:$H$83)*(((Schedule!$E$5:$E$83=A6)*(Schedule!$G$5:$G$83>Schedule!$H$5:$H$83))+((Schedule!$F$5:$F$83=A6)*(Schedule!$H$5:$H$83>Schedule!$G$5:$G$83)))) -> 0 | D6: =B6-C6 -> 0 | E6: =SUMPRODUCT((Schedule!$C$5:$C$83="Open 3.0")*(Schedule!$D$5:$D$83="League")*ISNUMBER(Schedule!$G$5:$G$83)*ISNUMBER(Schedule!$H$5:$H$83)*(((Schedule!$E$5:$E$83=A6)*Schedule!$G$5:$G$83)+((Schedule!$F$5:$F$83=A6)*Schedule!$H$5:$H$83))) -> 0 | F6: =SUMPRODUCT((Schedule!$C$5:$C$83="Open 3.0")*(Schedule!$D$5:$D$83="League")*ISNUMBER(Schedule!$G$5:$G$83)*ISNUMBER(Schedule!$H$5:$H$83)*(((Schedule!$E$5:$E$83=A6)*Schedule!$H$5:$H$83)+((Schedule!$F$5:$F$83=A6)*Schedule!$G$5:$G$83))) -> 0 | G6: =E6-F6 -> 0 | H6: =RANK(J6,$J$5:$J$10,0) -> 5 | J6: =C6*10000+G6*100+E6+ROW()/1000 -> 0.006
A7: Raja & Praveen | B7: =SUMPRODUCT((Schedule!$C$5:$C$83="Open 3.0")*(Schedule!$D$5:$D$83="League")*ISNUMBER(Schedule!$G$5:$G$83)*ISNUMBER(Schedule!$H$5:$H$83)*((Schedule!$E$5:$E$83=A7)+(Schedule!$F$5:$F$83=A7))) -> 0 | C7: =SUMPRODUCT((Schedule!$C$5:$C$83="Open 3.0")*(Schedule!$D$5:$D$83="League")*ISNUMBER(Schedule!$G$5:$G$83)*ISNUMBER(Schedule!$H$5:$H$83)*(((Schedule!$E$5:$E$83=A7)*(Schedule!$G$5:$G$83>Schedule!$H$5:$H$83))+((Schedule!$F$5:$F$83=A7)*(Schedule!$H$5:$H$83>Schedule!$G$5:$G$83)))) -> 0 | D7: =B7-C7 -> 0 | E7: =SUMPRODUCT((Schedule!$C$5:$C$83="Open 3.0")*(Schedule!$D$5:$D$83="League")*ISNUMBER(Schedule!$G$5:$G$83)*ISNUMBER(Schedule!$H$5:$H$83)*(((Schedule!$E$5:$E$83=A7)*Schedule!$G$5:$G$83)+((Schedule!$F$5:$F$83=A7)*Schedule!$H$5:$H$83))) -> 0 | F7: =SUMPRODUCT((Schedule!$C$5:$C$83="Open 3.0")*(Schedule!$D$5:$D$83="League")*ISNUMBER(Schedule!$G$5:$G$83)*ISNUMBER(Schedule!$H$5:$H$83)*(((Schedule!$E$5:$E$83=A7)*Schedule!$H$5:$H$83)+((Schedule!$F$5:$F$83=A7)*Schedule!$G$5:$G$83))) -> 0 | G7: =E7-F7 -> 0 | H7: =RANK(J7,$J$5:$J$10,0) -> 4 | J7: =C7*10000+G7*100+E7+ROW()/1000 -> 0.007
A8: Sunil Rajulapati & Chalapathi Rao | B8: =SUMPRODUCT((Schedule!$C$5:$C$83="Open 3.0")*(Schedule!$D$5:$D$83="League")*ISNUMBER(Schedule!$G$5:$G$83)*ISNUMBER(Schedule!$H$5:$H$83)*((Schedule!$E$5:$E$83=A8)+(Schedule!$F$5:$F$83=A8))) -> 0 | C8: =SUMPRODUCT((Schedule!$C$5:$C$83="Open 3.0")*(Schedule!$D$5:$D$83="League")*ISNUMBER(Schedule!$G$5:$G$83)*ISNUMBER(Schedule!$H$5:$H$83)*(((Schedule!$E$5:$E$83=A8)*(Schedule!$G$5:$G$83>Schedule!$H$5:$H$83))+((Schedule!$F$5:$F$83=A8)*(Schedule!$H$5:$H$83>Schedule!$G$5:$G$83)))) -> 0 | D8: =B8-C8 -> 0 | E8: =SUMPRODUCT((Schedule!$C$5:$C$83="Open 3.0")*(Schedule!$D$5:$D$83="League")*ISNUMBER(Schedule!$G$5:$G$83)*ISNUMBER(Schedule!$H$5:$H$83)*(((Schedule!$E$5:$E$83=A8)*Schedule!$G$5:$G$83)+((Schedule!$F$5:$F$83=A8)*Schedule!$H$5:$H$83))) -> 0 | F8: =SUMPRODUCT((Schedule!$C$5:$C$83="Open 3.0")*(Schedule!$D$5:$D$83="League")*ISNUMBER(Schedule!$G$5:$G$83)*ISNUMBER(Schedule!$H$5:$H$83)*(((Schedule!$E$5:$E$83=A8)*Schedule!$H$5:$H$83)+((Schedule!$F$5:$F$83=A8)*Schedule!$G$5:$G$83))) -> 0 | G8: =E8-F8 -> 0 | H8: =RANK(J8,$J$5:$J$10,0) -> 3 | J8: =C8*10000+G8*100+E8+ROW()/1000 -> 0.008
A9: Cody & Lexy | B9: =SUMPRODUCT((Schedule!$C$5:$C$83="Open 3.0")*(Schedule!$D$5:$D$83="League")*ISNUMBER(Schedule!$G$5:$G$83)*ISNUMBER(Schedule!$H$5:$H$83)*((Schedule!$E$5:$E$83=A9)+(Schedule!$F$5:$F$83=A9))) -> 0 | C9: =SUMPRODUCT((Schedule!$C$5:$C$83="Open 3.0")*(Schedule!$D$5:$D$83="League")*ISNUMBER(Schedule!$G$5:$G$83)*ISNUMBER(Schedule!$H$5:$H$83)*(((Schedule!$E$5:$E$83=A9)*(Schedule!$G$5:$G$83>Schedule!$H$5:$H$83))+((Schedule!$F$5:$F$83=A9)*(Schedule!$H$5:$H$83>Schedule!$G$5:$G$83)))) -> 0 | D9: =B9-C9 -> 0 | E9: =SUMPRODUCT((Schedule!$C$5:$C$83="Open 3.0")*(Schedule!$D$5:$D$83="League")*ISNUMBER(Schedule!$G$5:$G$83)*ISNUMBER(Schedule!$H$5:$H$83)*(((Schedule!$E$5:$E$83=A9)*Schedule!$G$5:$G$83)+((Schedule!$F$5:$F$83=A9)*Schedule!$H$5:$H$83))) -> 0 | F9: =SUMPRODUCT((Schedule!$C$5:$C$83="Open 3.0")*(Schedule!$D$5:$D$83="League")*ISNUMBER(Schedule!$G$5:$G$83)*ISNUMBER(Schedule!$H$5:$H$83)*(((Schedule!$E$5:$E$83=A9)*Schedule!$H$5:$H$83)+((Schedule!$F$5:$F$83=A9)*Schedule!$G$5:$G$83))) -> 0 | G9: =E9-F9 -> 0 | H9: =RANK(J9,$J$5:$J$10,0) -> 2 | J9: =C9*10000+G9*100+E9+ROW()/1000 -> 0.009
A10: Ramesh & Kelly | B10: =SUMPRODUCT((Schedule!$C$5:$C$83="Open 3.0")*(Schedule!$D$5:$D$83="League")*ISNUMBER(Schedule!$G$5:$G$83)*ISNUMBER(Schedule!$H$5:$H$83)*((Schedule!$E$5:$E$83=A10)+(Schedule!$F$5:$F$83=A10))) -> 0 | C10: =SUMPRODUCT((Schedule!$C$5:$C$83="Open 3.0")*(Schedule!$D$5:$D$83="League")*ISNUMBER(Schedule!$G$5:$G$83)*ISNUMBER(Schedule!$H$5:$H$83)*(((Schedule!$E$5:$E$83=A10)*(Schedule!$G$5:$G$83>Schedule!$H$5:$H$83))+((Schedule!$F$5:$F$83=A10)*(Schedule!$H$5:$H$83>Schedule!$G$5:$G$83)))) -> 0 | D10: =B10-C10 -> 0 | E10: =SUMPRODUCT((Schedule!$C$5:$C$83="Open 3.0")*(Schedule!$D$5:$D$83="League")*ISNUMBER(Schedule!$G$5:$G$83)*ISNUMBER(Schedule!$H$5:$H$83)*(((Schedule!$E$5:$E$83=A10)*Schedule!$G$5:$G$83)+((Schedule!$F$5:$F$83=A10)*Schedule!$H$5:$H$83))) -> 0 | F10: =SUMPRODUCT((Schedule!$C$5:$C$83="Open 3.0")*(Schedule!$D$5:$D$83="League")*ISNUMBER(Schedule!$G$5:$G$83)*ISNUMBER(Schedule!$H$5:$H$83)*(((Schedule!$E$5:$E$83=A10)*Schedule!$H$5:$H$83)+((Schedule!$F$5:$F$83=A10)*Schedule!$G$5:$G$83))) -> 0 | G10: =E10-F10 -> 0 | H10: =RANK(J10,$J$5:$J$10,0) -> 1 | J10: =C10*10000+G10*100+E10+ROW()/1000 -> 0.01
A12: Green rows qualify. Tie on wins, +/- and points for: decide by head-to-head on the Schedule tab.

Sheet Open 3.5
A1: Open 3.5 — standings (updates as you type scores on the Schedule tab)
A2: Top 4 go to the semis: 1 v 4 and 2 v 3. Rank: wins, then +/-, then points for.
A4: Team | B4: Played | C4: Won | D4: Lost | E4: Points for | F4: Points against | G4: +/- | H4: Rank
A5: Venkat & Immanuel | B5: =SUMPRODUCT((Schedule!$C$5:$C$83="Open 3.5")*(Schedule!$D$5:$D$83="League")*ISNUMBER(Schedule!$G$5:$G$83)*ISNUMBER(Schedule!$H$5:$H$83)*((Schedule!$E$5:$E$83=A5)+(Schedule!$F$5:$F$83=A5))) -> 0 | C5: =SUMPRODUCT((Schedule!$C$5:$C$83="Open 3.5")*(Schedule!$D$5:$D$83="League")*ISNUMBER(Schedule!$G$5:$G$83)*ISNUMBER(Schedule!$H$5:$H$83)*(((Schedule!$E$5:$E$83=A5)*(Schedule!$G$5:$G$83>Schedule!$H$5:$H$83))+((Schedule!$F$5:$F$83=A5)*(Schedule!$H$5:$H$83>Schedule!$G$5:$G$83)))) -> 0 | D5: =B5-C5 -> 0 | E5: =SUMPRODUCT((Schedule!$C$5:$C$83="Open 3.5")*(Schedule!$D$5:$D$83="League")*ISNUMBER(Schedule!$G$5:$G$83)*ISNUMBER(Schedule!$H$5:$H$83)*(((Schedule!$E$5:$E$83=A5)*Schedule!$G$5:$G$83)+((Schedule!$F$5:$F$83=A5)*Schedule!$H$5:$H$83))) -> 0 | F5: =SUMPRODUCT((Schedule!$C$5:$C$83="Open 3.5")*(Schedule!$D$5:$D$83="League")*ISNUMBER(Schedule!$G$5:$G$83)*ISNUMBER(Schedule!$H$5:$H$83)*(((Schedule!$E$5:$E$83=A5)*Schedule!$H$5:$H$83)+((Schedule!$F$5:$F$83=A5)*Schedule!$G$5:$G$83))) -> 0 | G5: =E5-F5 -> 0 | H5: =RANK(J5,$J$5:$J$14,0) -> 10 | J5: =C5*10000+G5*100+E5+ROW()/1000 -> 0.005
A6: GV Lakshman & Brad Salyers | B6: =SUMPRODUCT((Schedule!$C$5:$C$83="Open 3.5")*(Schedule!$D$5:$D$83="League")*ISNUMBER(Schedule!$G$5:$G$83)*ISNUMBER(Schedule!$H$5:$H$83)*((Schedule!$E$5:$E$83=A6)+(Schedule!$F$5:$F$83=A6))) -> 0 | C6: =SUMPRODUCT((Schedule!$C$5:$C$83="Open 3.5")*(Schedule!$D$5:$D$83="League")*ISNUMBER(Schedule!$G$5:$G$83)*ISNUMBER(Schedule!$H$5:$H$83)*(((Schedule!$E$5:$E$83=A6)*(Schedule!$G$5:$G$83>Schedule!$H$5:$H$83))+((Schedule!$F$5:$F$83=A6)*(Schedule!$H$5:$H$83>Schedule!$G$5:$G$83)))) -> 0 | D6: =B6-C6 -> 0 | E6: =SUMPRODUCT((Schedule!$C$5:$C$83="Open 3.5")*(Schedule!$D$5:$D$83="League")*ISNUMBER(Schedule!$G$5:$G$83)*ISNUMBER(Schedule!$H$5:$H$83)*(((Schedule!$E$5:$E$83=A6)*Schedule!$G$5:$G$83)+((Schedule!$F$5:$F$83=A6)*Schedule!$H$5:$H$83))) -> 0 | F6: =SUMPRODUCT((Schedule!$C$5:$C$83="Open 3.5")*(Schedule!$D$5:$D$83="League")*ISNUMBER(Schedule!$G$5:$G$83)*ISNUMBER(Schedule!$H$5:$H$83)*(((Schedule!$E$5:$E$83=A6)*Schedule!$H$5:$H$83)+((Schedule!$F$5:$F$83=A6)*Schedule!$G$5:$G$83))) -> 0 | G6: =E6-F6 -> 0 | H6: =RANK(J6,$J$5:$J$14,0) -> 9 | J6: =C6*10000+G6*100+E6+ROW()/1000 -> 0.006
A7: Vamsi & Vanith | B7: =SUMPRODUCT((Schedule!$C$5:$C$83="Open 3.5")*(Schedule!$D$5:$D$83="League")*ISNUMBER(Schedule!$G$5:$G$83)*ISNUMBER(Schedule!$H$5:$H$83)*((Schedule!$E$5:$E$83=A7)+(Schedule!$F$5:$F$83=A7))) -> 0 | C7: =SUMPRODUCT((Schedule!$C$5:$C$83="Open 3.5")*(Schedule!$D$5:$D$83="League")*ISNUMBER(Schedule!$G$5:$G$83)*ISNUMBER(Schedule!$H$5:$H$83)*(((Schedule!$E$5:$E$83=A7)*(Schedule!$G$5:$G$83>Schedule!$H$5:$H$83))+((Schedule!$F$5:$F$83=A7)*(Schedule!$H$5:$H$83>Schedule!$G$5:$G$83)))) -> 0 | D7: =B7-C7 -> 0 | E7: =SUMPRODUCT((Schedule!$C$5:$C$83="Open 3.5")*(Schedule!$D$5:$D$83="League")*ISNUMBER(Schedule!$G$5:$G$83)*ISNUMBER(Schedule!$H$5:$H$83)*(((Schedule!$E$5:$E$83=A7)*Schedule!$G$5:$G$83)+((Schedule!$F$5:$F$83=A7)*Schedule!$H$5:$H$83))) -> 0 | F7: =SUMPRODUCT((Schedule!$C$5:$C$83="Open 3.5")*(Schedule!$D$5:$D$83="League")*ISNUMBER(Schedule!$G$5:$G$83)*ISNUMBER(Schedule!$H$5:$H$83)*(((Schedule!$E$5:$E$83=A7)*Schedule!$H$5:$H$83)+((Schedule!$F$5:$F$83=A7)*Schedule!$G$5:$G$83))) -> 0 | G7: =E7-F7 -> 0 | H7: =RANK(J7,$J$5:$J$14,0) -> 8 | J7: =C7*10000+G7*100+E7+ROW()/1000 -> 0.007
A8: Singa & Sekar | B8: =SUMPRODUCT((Schedule!$C$5:$C$83="Open 3.5")*(Schedule!$D$5:$D$83="League")*ISNUMBER(Schedule!$G$5:$G$83)*ISNUMBER(Schedule!$H$5:$H$83)*((Schedule!$E$5:$E$83=A8)+(Schedule!$F$5:$F$83=A8))) -> 0 | C8: =SUMPRODUCT((Schedule!$C$5:$C$83="Open 3.5")*(Schedule!$D$5:$D$83="League")*ISNUMBER(Schedule!$G$5:$G$83)*ISNUMBER(Schedule!$H$5:$H$83)*(((Schedule!$E$5:$E$83=A8)*(Schedule!$G$5:$G$83>Schedule!$H$5:$H$83))+((Schedule!$F$5:$F$83=A8)*(Schedule!$H$5:$H$83>Schedule!$G$5:$G$83)))) -> 0 | D8: =B8-C8 -> 0 | E8: =SUMPRODUCT((Schedule!$C$5:$C$83="Open 3.5")*(Schedule!$D$5:$D$83="League")*ISNUMBER(Schedule!$G$5:$G$83)*ISNUMBER(Schedule!$H$5:$H$83)*(((Schedule!$E$5:$E$83=A8)*Schedule!$G$5:$G$83)+((Schedule!$F$5:$F$83=A8)*Schedule!$H$5:$H$83))) -> 0 | F8: =SUMPRODUCT((Schedule!$C$5:$C$83="Open 3.5")*(Schedule!$D$5:$D$83="League")*ISNUMBER(Schedule!$G$5:$G$83)*ISNUMBER(Schedule!$H$5:$H$83)*(((Schedule!$E$5:$E$83=A8)*Schedule!$H$5:$H$83)+((Schedule!$F$5:$F$83=A8)*Schedule!$G$5:$G$83))) -> 0 | G8: =E8-F8 -> 0 | H8: =RANK(J8,$J$5:$J$14,0) -> 7 | J8: =C8*10000+G8*100+E8+ROW()/1000 -> 0.008
A9: Hari & Madhu | B9: =SUMPRODUCT((Schedule!$C$5:$C$83="Open 3.5")*(Schedule!$D$5:$D$83="League")*ISNUMBER(Schedule!$G$5:$G$83)*ISNUMBER(Schedule!$H$5:$H$83)*((Schedule!$E$5:$E$83=A9)+(Schedule!$F$5:$F$83=A9))) -> 0 | C9: =SUMPRODUCT((Schedule!$C$5:$C$83="Open 3.5")*(Schedule!$D$5:$D$83="League")*ISNUMBER(Schedule!$G$5:$G$83)*ISNUMBER(Schedule!$H$5:$H$83)*(((Schedule!$E$5:$E$83=A9)*(Schedule!$G$5:$G$83>Schedule!$H$5:$H$83))+((Schedule!$F$5:$F$83=A9)*(Schedule!$H$5:$H$83>Schedule!$G$5:$G$83)))) -> 0 | D9: =B9-C9 -> 0 | E9: =SUMPRODUCT((Schedule!$C$5:$C$83="Open 3.5")*(Schedule!$D$5:$D$83="League")*ISNUMBER(Schedule!$G$5:$G$83)*ISNUMBER(Schedule!$H$5:$H$83)*(((Schedule!$E$5:$E$83=A9)*Schedule!$G$5:$G$83)+((Schedule!$F$5:$F$83=A9)*Schedule!$H$5:$H$83))) -> 0 | F9: =SUMPRODUCT((Schedule!$C$5:$C$83="Open 3.5")*(Schedule!$D$5:$D$83="League")*ISNUMBER(Schedule!$G$5:$G$83)*ISNUMBER(Schedule!$H$5:$H$83)*(((Schedule!$E$5:$E$83=A9)*Schedule!$H$5:$H$83)+((Schedule!$F$5:$F$83=A9)*Schedule!$G$5:$G$83))) -> 0 | G9: =E9-F9 -> 0 | H9: =RANK(J9,$J$5:$J$14,0) -> 6 | J9: =C9*10000+G9*100+E9+ROW()/1000 -> 0.009
A10: Sandeep & Jagan | B10: =SUMPRODUCT((Schedule!$C$5:$C$83="Open 3.5")*(Schedule!$D$5:$D$83="League")*ISNUMBER(Schedule!$G$5:$G$83)*ISNUMBER(Schedule!$H$5:$H$83)*((Schedule!$E$5:$E$83=A10)+(Schedule!$F$5:$F$83=A10))) -> 0 | C10: =SUMPRODUCT((Schedule!$C$5:$C$83="Open 3.5")*(Schedule!$D$5:$D$83="League")*ISNUMBER(Schedule!$G$5:$G$83)*ISNUMBER(Schedule!$H$5:$H$83)*(((Schedule!$E$5:$E$83=A10)*(Schedule!$G$5:$G$83>Schedule!$H$5:$H$83))+((Schedule!$F$5:$F$83=A10)*(Schedule!$H$5:$H$83>Schedule!$G$5:$G$83)))) -> 0 | D10: =B10-C10 -> 0 | E10: =SUMPRODUCT((Schedule!$C$5:$C$83="Open 3.5")*(Schedule!$D$5:$D$83="League")*ISNUMBER(Schedule!$G$5:$G$83)*ISNUMBER(Schedule!$H$5:$H$83)*(((Schedule!$E$5:$E$83=A10)*Schedule!$G$5:$G$83)+((Schedule!$F$5:$F$83=A10)*Schedule!$H$5:$H$83))) -> 0 | F10: =SUMPRODUCT((Schedule!$C$5:$C$83="Open 3.5")*(Schedule!$D$5:$D$83="League")*ISNUMBER(Schedule!$G$5:$G$83)*ISNUMBER(Schedule!$H$5:$H$83)*(((Schedule!$E$5:$E$83=A10)*Schedule!$H$5:$H$83)+((Schedule!$F$5:$F$83=A10)*Schedule!$G$5:$G$83))) -> 0 | G10: =E10-F10 -> 0 | H10: =RANK(J10,$J$5:$J$14,0) -> 5 | J10: =C10*10000+G10*100+E10+ROW()/1000 -> 0.01
A11: Satish & Mahesh | B11: =SUMPRODUCT((Schedule!$C$5:$C$83="Open 3.5")*(Schedule!$D$5:$D$83="League")*ISNUMBER(Schedule!$G$5:$G$83)*ISNUMBER(Schedule!$H$5:$H$83)*((Schedule!$E$5:$E$83=A11)+(Schedule!$F$5:$F$83=A11))) -> 0 | C11: =SUMPRODUCT((Schedule!$C$5:$C$83="Open 3.5")*(Schedule!$D$5:$D$83="League")*ISNUMBER(Schedule!$G$5:$G$83)*ISNUMBER(Schedule!$H$5:$H$83)*(((Schedule!$E$5:$E$83=A11)*(Schedule!$G$5:$G$83>Schedule!$H$5:$H$83))+((Schedule!$F$5:$F$83=A11)*(Schedule!$H$5:$H$83>Schedule!$G$5:$G$83)))) -> 0 | D11: =B11-C11 -> 0 | E11: =SUMPRODUCT((Schedule!$C$5:$C$83="Open 3.5")*(Schedule!$D$5:$D$83="League")*ISNUMBER(Schedule!$G$5:$G$83)*ISNUMBER(Schedule!$H$5:$H$83)*(((Schedule!$E$5:$E$83=A11)*Schedule!$G$5:$G$83)+((Schedule!$F$5:$F$83=A11)*Schedule!$H$5:$H$83))) -> 0 | F11: =SUMPRODUCT((Schedule!$C$5:$C$83="Open 3.5")*(Schedule!$D$5:$D$83="League")*ISNUMBER(Schedule!$G$5:$G$83)*ISNUMBER(Schedule!$H$5:$H$83)*(((Schedule!$E$5:$E$83=A11)*Schedule!$H$5:$H$83)+((Schedule!$F$5:$F$83=A11)*Schedule!$G$5:$G$83))) -> 0 | G11: =E11-F11 -> 0 | H11: =RANK(J11,$J$5:$J$14,0) -> 4 | J11: =C11*10000+G11*100+E11+ROW()/1000 -> 0.011
A12: Thiru & Gitanshu | B12: =SUMPRODUCT((Schedule!$C$5:$C$83="Open 3.5")*(Schedule!$D$5:$D$83="League")*ISNUMBER(Schedule!$G$5:$G$83)*ISNUMBER(Schedule!$H$5:$H$83)*((Schedule!$E$5:$E$83=A12)+(Schedule!$F$5:$F$83=A12))) -> 0 | C12: =SUMPRODUCT((Schedule!$C$5:$C$83="Open 3.5")*(Schedule!$D$5:$D$83="League")*ISNUMBER(Schedule!$G$5:$G$83)*ISNUMBER(Schedule!$H$5:$H$83)*(((Schedule!$E$5:$E$83=A12)*(Schedule!$G$5:$G$83>Schedule!$H$5:$H$83))+((Schedule!$F$5:$F$83=A12)*(Schedule!$H$5:$H$83>Schedule!$G$5:$G$83)))) -> 0 | D12: =B12-C12 -> 0 | E12: =SUMPRODUCT((Schedule!$C$5:$C$83="Open 3.5")*(Schedule!$D$5:$D$83="League")*ISNUMBER(Schedule!$G$5:$G$83)*ISNUMBER(Schedule!$H$5:$H$83)*(((Schedule!$E$5:$E$83=A12)*Schedule!$G$5:$G$83)+((Schedule!$F$5:$F$83=A12)*Schedule!$H$5:$H$83))) -> 0 | F12: =SUMPRODUCT((Schedule!$C$5:$C$83="Open 3.5")*(Schedule!$D$5:$D$83="League")*ISNUMBER(Schedule!$G$5:$G$83)*ISNUMBER(Schedule!$H$5:$H$83)*(((Schedule!$E$5:$E$83=A12)*Schedule!$H$5:$H$83)+((Schedule!$F$5:$F$83=A12)*Schedule!$G$5:$G$83))) -> 0 | G12: =E12-F12 -> 0 | H12: =RANK(J12,$J$5:$J$14,0) -> 3 | J12: =C12*10000+G12*100+E12+ROW()/1000 -> 0.012
A13: Shari & Michelle | B13: =SUMPRODUCT((Schedule!$C$5:$C$83="Open 3.5")*(Schedule!$D$5:$D$83="League")*ISNUMBER(Schedule!$G$5:$G$83)*ISNUMBER(Schedule!$H$5:$H$83)*((Schedule!$E$5:$E$83=A13)+(Schedule!$F$5:$F$83=A13))) -> 0 | C13: =SUMPRODUCT((Schedule!$C$5:$C$83="Open 3.5")*(Schedule!$D$5:$D$83="League")*ISNUMBER(Schedule!$G$5:$G$83)*ISNUMBER(Schedule!$H$5:$H$83)*(((Schedule!$E$5:$E$83=A13)*(Schedule!$G$5:$G$83>Schedule!$H$5:$H$83))+((Schedule!$F$5:$F$83=A13)*(Schedule!$H$5:$H$83>Schedule!$G$5:$G$83)))) -> 0 | D13: =B13-C13 -> 0 | E13: =SUMPRODUCT((Schedule!$C$5:$C$83="Open 3.5")*(Schedule!$D$5:$D$83="League")*ISNUMBER(Schedule!$G$5:$G$83)*ISNUMBER(Schedule!$H$5:$H$83)*(((Schedule!$E$5:$E$83=A13)*Schedule!$G$5:$G$83)+((Schedule!$F$5:$F$83=A13)*Schedule!$H$5:$H$83))) -> 0 | F13: =SUMPRODUCT((Schedule!$C$5:$C$83="Open 3.5")*(Schedule!$D$5:$D$83="League")*ISNUMBER(Schedule!$G$5:$G$83)*ISNUMBER(Schedule!$H$5:$H$83)*(((Schedule!$E$5:$E$83=A13)*Schedule!$H$5:$H$83)+((Schedule!$F$5:$F$83=A13)*Schedule!$G$5:$G$83))) -> 0 | G13: =E13-F13 -> 0 | H13: =RANK(J13,$J$5:$J$14,0) -> 2 | J13: =C13*10000+G13*100+E13+ROW()/1000 -> 0.013
A14: Scott & Harshad | B14: =SUMPRODUCT((Schedule!$C$5:$C$83="Open 3.5")*(Schedule!$D$5:$D$83="League")*ISNUMBER(Schedule!$G$5:$G$83)*ISNUMBER(Schedule!$H$5:$H$83)*((Schedule!$E$5:$E$83=A14)+(Schedule!$F$5:$F$83=A14))) -> 0 | C14: =SUMPRODUCT((Schedule!$C$5:$C$83="Open 3.5")*(Schedule!$D$5:$D$83="League")*ISNUMBER(Schedule!$G$5:$G$83)*ISNUMBER(Schedule!$H$5:$H$83)*(((Schedule!$E$5:$E$83=A14)*(Schedule!$G$5:$G$83>Schedule!$H$5:$H$83))+((Schedule!$F$5:$F$83=A14)*(Schedule!$H$5:$H$83>Schedule!$G$5:$G$83)))) -> 0 | D14: =B14-C14 -> 0 | E14: =SUMPRODUCT((Schedule!$C$5:$C$83="Open 3.5")*(Schedule!$D$5:$D$83="League")*ISNUMBER(Schedule!$G$5:$G$83)*ISNUMBER(Schedule!$H$5:$H$83)*(((Schedule!$E$5:$E$83=A14)*Schedule!$G$5:$G$83)+((Schedule!$F$5:$F$83=A14)*Schedule!$H$5:$H$83))) -> 0 | F14: =SUMPRODUCT((Schedule!$C$5:$C$83="Open 3.5")*(Schedule!$D$5:$D$83="League")*ISNUMBER(Schedule!$G$5:$G$83)*ISNUMBER(Schedule!$H$5:$H$83)*(((Schedule!$E$5:$E$83=A14)*Schedule!$H$5:$H$83)+((Schedule!$F$5:$F$83=A14)*Schedule!$G$5:$G$83))) -> 0 | G14: =E14-F14 -> 0 | H14: =RANK(J14,$J$5:$J$14,0) -> 1 | J14: =C14*10000+G14*100+E14+ROW()/1000 -> 0.014
A16: Green rows qualify. Tie on wins, +/- and points for: decide by head-to-head on the Schedule tab.

Sheet Mixed Doubles
A1: Mixed Doubles — standings (updates as you type scores on the Schedule tab)
A2: Top 4 go to the semis: 1 v 4 and 2 v 3. Rank: wins, then +/-, then points for.
A4: Team | B4: Played | C4: Won | D4: Lost | E4: Points for | F4: Points against | G4: +/- | H4: Rank
A5: Ramesh & Kelly | B5: =SUMPRODUCT((Schedule!$C$5:$C$83="Mixed Doubles")*(Schedule!$D$5:$D$83="League")*ISNUMBER(Schedule!$G$5:$G$83)*ISNUMBER(Schedule!$H$5:$H$83)*((Schedule!$E$5:$E$83=A5)+(Schedule!$F$5:$F$83=A5))) -> 0 | C5: =SUMPRODUCT((Schedule!$C$5:$C$83="Mixed Doubles")*(Schedule!$D$5:$D$83="League")*ISNUMBER(Schedule!$G$5:$G$83)*ISNUMBER(Schedule!$H$5:$H$83)*(((Schedule!$E$5:$E$83=A5)*(Schedule!$G$5:$G$83>Schedule!$H$5:$H$83))+((Schedule!$F$5:$F$83=A5)*(Schedule!$H$5:$H$83>Schedule!$G$5:$G$83)))) -> 0 | D5: =B5-C5 -> 0 | E5: =SUMPRODUCT((Schedule!$C$5:$C$83="Mixed Doubles")*(Schedule!$D$5:$D$83="League")*ISNUMBER(Schedule!$G$5:$G$83)*ISNUMBER(Schedule!$H$5:$H$83)*(((Schedule!$E$5:$E$83=A5)*Schedule!$G$5:$G$83)+((Schedule!$F$5:$F$83=A5)*Schedule!$H$5:$H$83))) -> 0 | F5: =SUMPRODUCT((Schedule!$C$5:$C$83="Mixed Doubles")*(Schedule!$D$5:$D$83="League")*ISNUMBER(Schedule!$G$5:$G$83)*ISNUMBER(Schedule!$H$5:$H$83)*(((Schedule!$E$5:$E$83=A5)*Schedule!$H$5:$H$83)+((Schedule!$F$5:$F$83=A5)*Schedule!$G$5:$G$83))) -> 0 | G5: =E5-F5 -> 0 | H5: =RANK(J5,$J$5:$J$10,0) -> 6 | J5: =C5*10000+G5*100+E5+ROW()/1000 -> 0.005
A6: Elango & Ramya | B6: =SUMPRODUCT((Schedule!$C$5:$C$83="Mixed Doubles")*(Schedule!$D$5:$D$83="League")*ISNUMBER(Schedule!$G$5:$G$83)*ISNUMBER(Schedule!$H$5:$H$83)*((Schedule!$E$5:$E$83=A6)+(Schedule!$F$5:$F$83=A6))) -> 0 | C6: =SUMPRODUCT((Schedule!$C$5:$C$83="Mixed Doubles")*(Schedule!$D$5:$D$83="League")*ISNUMBER(Schedule!$G$5:$G$83)*ISNUMBER(Schedule!$H$5:$H$83)*(((Schedule!$E$5:$E$83=A6)*(Schedule!$G$5:$G$83>Schedule!$H$5:$H$83))+((Schedule!$F$5:$F$83=A6)*(Schedule!$H$5:$H$83>Schedule!$G$5:$G$83)))) -> 0 | D6: =B6-C6 -> 0 | E6: =SUMPRODUCT((Schedule!$C$5:$C$83="Mixed Doubles")*(Schedule!$D$5:$D$83="League")*ISNUMBER(Schedule!$G$5:$G$83)*ISNUMBER(Schedule!$H$5:$H$83)*(((Schedule!$E$5:$E$83=A6)*Schedule!$G$5:$G$83)+((Schedule!$F$5:$F$83=A6)*Schedule!$H$5:$H$83))) -> 0 | F6: =SUMPRODUCT((Schedule!$C$5:$C$83="Mixed Doubles")*(Schedule!$D$5:$D$83="League")*ISNUMBER(Schedule!$G$5:$G$83)*ISNUMBER(Schedule!$H$5:$H$83)*(((Schedule!$E$5:$E$83=A6)*Schedule!$H$5:$H$83)+((Schedule!$F$5:$F$83=A6)*Schedule!$G$5:$G$83))) -> 0 | G6: =E6-F6 -> 0 | H6: =RANK(J6,$J$5:$J$10,0) -> 5 | J6: =C6*10000+G6*100+E6+ROW()/1000 -> 0.006
A7: Dwayne & Shari | B7: =SUMPRODUCT((Schedule!$C$5:$C$83="Mixed Doubles")*(Schedule!$D$5:$D$83="League")*ISNUMBER(Schedule!$G$5:$G$83)*ISNUMBER(Schedule!$H$5:$H$83)*((Schedule!$E$5:$E$83=A7)+(Schedule!$F$5:$F$83=A7))) -> 0 | C7: =SUMPRODUCT((Schedule!$C$5:$C$83="Mixed Doubles")*(Schedule!$D$5:$D$83="League")*ISNUMBER(Schedule!$G$5:$G$83)*ISNUMBER(Schedule!$H$5:$H$83)*(((Schedule!$E$5:$E$83=A7)*(Schedule!$G$5:$G$83>Schedule!$H$5:$H$83))+((Schedule!$F$5:$F$83=A7)*(Schedule!$H$5:$H$83>Schedule!$G$5:$G$83)))) -> 0 | D7: =B7-C7 -> 0 | E7: =SUMPRODUCT((Schedule!$C$5:$C$83="Mixed Doubles")*(Schedule!$D$5:$D$83="League")*ISNUMBER(Schedule!$G$5:$G$83)*ISNUMBER(Schedule!$H$5:$H$83)*(((Schedule!$E$5:$E$83=A7)*Schedule!$G$5:$G$83)+((Schedule!$F$5:$F$83=A7)*Schedule!$H$5:$H$83))) -> 0 | F7: =SUMPRODUCT((Schedule!$C$5:$C$83="Mixed Doubles")*(Schedule!$D$5:$D$83="League")*ISNUMBER(Schedule!$G$5:$G$83)*ISNUMBER(Schedule!$H$5:$H$83)*(((Schedule!$E$5:$E$83=A7)*Schedule!$H$5:$H$83)+((Schedule!$F$5:$F$83=A7)*Schedule!$G$5:$G$83))) -> 0 | G7: =E7-F7 -> 0 | H7: =RANK(J7,$J$5:$J$10,0) -> 4 | J7: =C7*10000+G7*100+E7+ROW()/1000 -> 0.007
A8: Cody & Lexy | B8: =SUMPRODUCT((Schedule!$C$5:$C$83="Mixed Doubles")*(Schedule!$D$5:$D$83="League")*ISNUMBER(Schedule!$G$5:$G$83)*ISNUMBER(Schedule!$H$5:$H$83)*((Schedule!$E$5:$E$83=A8)+(Schedule!$F$5:$F$83=A8))) -> 0 | C8: =SUMPRODUCT((Schedule!$C$5:$C$83="Mixed Doubles")*(Schedule!$D$5:$D$83="League")*ISNUMBER(Schedule!$G$5:$G$83)*ISNUMBER(Schedule!$H$5:$H$83)*(((Schedule!$E$5:$E$83=A8)*(Schedule!$G$5:$G$83>Schedule!$H$5:$H$83))+((Schedule!$F$5:$F$83=A8)*(Schedule!$H$5:$H$83>Schedule!$G$5:$G$83)))) -> 0 | D8: =B8-C8 -> 0 | E8: =SUMPRODUCT((Schedule!$C$5:$C$83="Mixed Doubles")*(Schedule!$D$5:$D$83="League")*ISNUMBER(Schedule!$G$5:$G$83)*ISNUMBER(Schedule!$H$5:$H$83)*(((Schedule!$E$5:$E$83=A8)*Schedule!$G$5:$G$83)+((Schedule!$F$5:$F$83=A8)*Schedule!$H$5:$H$83))) -> 0 | F8: =SUMPRODUCT((Schedule!$C$5:$C$83="Mixed Doubles")*(Schedule!$D$5:$D$83="League")*ISNUMBER(Schedule!$G$5:$G$83)*ISNUMBER(Schedule!$H$5:$H$83)*(((Schedule!$E$5:$E$83=A8)*Schedule!$H$5:$H$83)+((Schedule!$F$5:$F$83=A8)*Schedule!$G$5:$G$83))) -> 0 | G8: =E8-F8 -> 0 | H8: =RANK(J8,$J$5:$J$10,0) -> 3 | J8: =C8*10000+G8*100+E8+ROW()/1000 -> 0.008
A9: Alexis & Chris | B9: =SUMPRODUCT((Schedule!$C$5:$C$83="Mixed Doubles")*(Schedule!$D$5:$D$83="League")*ISNUMBER(Schedule!$G$5:$G$83)*ISNUMBER(Schedule!$H$5:$H$83)*((Schedule!$E$5:$E$83=A9)+(Schedule!$F$5:$F$83=A9))) -> 0 | C9: =SUMPRODUCT((Schedule!$C$5:$C$83="Mixed Doubles")*(Schedule!$D$5:$D$83="League")*ISNUMBER(Schedule!$G$5:$G$83)*ISNUMBER(Schedule!$H$5:$H$83)*(((Schedule!$E$5:$E$83=A9)*(Schedule!$G$5:$G$83>Schedule!$H$5:$H$83))+((Schedule!$F$5:$F$83=A9)*(Schedule!$H$5:$H$83>Schedule!$G$5:$G$83)))) -> 0 | D9: =B9-C9 -> 0 | E9: =SUMPRODUCT((Schedule!$C$5:$C$83="Mixed Doubles")*(Schedule!$D$5:$D$83="League")*ISNUMBER(Schedule!$G$5:$G$83)*ISNUMBER(Schedule!$H$5:$H$83)*(((Schedule!$E$5:$E$83=A9)*Schedule!$G$5:$G$83)+((Schedule!$F$5:$F$83=A9)*Schedule!$H$5:$H$83))) -> 0 | F9: =SUMPRODUCT((Schedule!$C$5:$C$83="Mixed Doubles")*(Schedule!$D$5:$D$83="League")*ISNUMBER(Schedule!$G$5:$G$83)*ISNUMBER(Schedule!$H$5:$H$83)*(((Schedule!$E$5:$E$83=A9)*Schedule!$H$5:$H$83)+((Schedule!$F$5:$F$83=A9)*Schedule!$G$5:$G$83))) -> 0 | G9: =E9-F9 -> 0 | H9: =RANK(J9,$J$5:$J$10,0) -> 2 | J9: =C9*10000+G9*100+E9+ROW()/1000 -> 0.009
A10: Tim & Martha | B10: =SUMPRODUCT((Schedule!$C$5:$C$83="Mixed Doubles")*(Schedule!$D$5:$D$83="League")*ISNUMBER(Schedule!$G$5:$G$83)*ISNUMBER(Schedule!$H$5:$H$83)*((Schedule!$E$5:$E$83=A10)+(Schedule!$F$5:$F$83=A10))) -> 0 | C10: =SUMPRODUCT((Schedule!$C$5:$C$83="Mixed Doubles")*(Schedule!$D$5:$D$83="League")*ISNUMBER(Schedule!$G$5:$G$83)*ISNUMBER(Schedule!$H$5:$H$83)*(((Schedule!$E$5:$E$83=A10)*(Schedule!$G$5:$G$83>Schedule!$H$5:$H$83))+((Schedule!$F$5:$F$83=A10)*(Schedule!$H$5:$H$83>Schedule!$G$5:$G$83)))) -> 0 | D10: =B10-C10 -> 0 | E10: =SUMPRODUCT((Schedule!$C$5:$C$83="Mixed Doubles")*(Schedule!$D$5:$D$83="League")*ISNUMBER(Schedule!$G$5:$G$83)*ISNUMBER(Schedule!$H$5:$H$83)*(((Schedule!$E$5:$E$83=A10)*Schedule!$G$5:$G$83)+((Schedule!$F$5:$F$83=A10)*Schedule!$H$5:$H$83))) -> 0 | F10: =SUMPRODUCT((Schedule!$C$5:$C$83="Mixed Doubles")*(Schedule!$D$5:$D$83="League")*ISNUMBER(Schedule!$G$5:$G$83)*ISNUMBER(Schedule!$H$5:$H$83)*(((Schedule!$E$5:$E$83=A10)*Schedule!$H$5:$H$83)+((Schedule!$F$5:$F$83=A10)*Schedule!$G$5:$G$83))) -> 0 | G10: =E10-F10 -> 0 | H10: =RANK(J10,$J$5:$J$10,0) -> 1 | J10: =C10*10000+G10*100+E10+ROW()/1000 -> 0.01
A12: Green rows qualify. Tie on wins, +/- and points for: decide by head-to-head on the Schedule tab.

Sheet Open 4.0
A1: Open 4.0 — standings (updates as you type scores on the Schedule tab)
A2: Top 4 go to the semis: 1 v 4 and 2 v 3. Rank: wins, then +/-, then points for.
A4: Team | B4: Played | C4: Won | D4: Lost | E4: Points for | F4: Points against | G4: +/- | H4: Rank
A5: Vinod & Senthil | B5: =SUMPRODUCT((Schedule!$C$5:$C$83="Open 4.0")*(Schedule!$D$5:$D$83="League")*ISNUMBER(Schedule!$G$5:$G$83)*ISNUMBER(Schedule!$H$5:$H$83)*((Schedule!$E$5:$E$83=A5)+(Schedule!$F$5:$F$83=A5))) -> 0 | C5: =SUMPRODUCT((Schedule!$C$5:$C$83="Open 4.0")*(Schedule!$D$5:$D$83="League")*ISNUMBER(Schedule!$G$5:$G$83)*ISNUMBER(Schedule!$H$5:$H$83)*(((Schedule!$E$5:$E$83=A5)*(Schedule!$G$5:$G$83>Schedule!$H$5:$H$83))+((Schedule!$F$5:$F$83=A5)*(Schedule!$H$5:$H$83>Schedule!$G$5:$G$83)))) -> 0 | D5: =B5-C5 -> 0 | E5: =SUMPRODUCT((Schedule!$C$5:$C$83="Open 4.0")*(Schedule!$D$5:$D$83="League")*ISNUMBER(Schedule!$G$5:$G$83)*ISNUMBER(Schedule!$H$5:$H$83)*(((Schedule!$E$5:$E$83=A5)*Schedule!$G$5:$G$83)+((Schedule!$F$5:$F$83=A5)*Schedule!$H$5:$H$83))) -> 0 | F5: =SUMPRODUCT((Schedule!$C$5:$C$83="Open 4.0")*(Schedule!$D$5:$D$83="League")*ISNUMBER(Schedule!$G$5:$G$83)*ISNUMBER(Schedule!$H$5:$H$83)*(((Schedule!$E$5:$E$83=A5)*Schedule!$H$5:$H$83)+((Schedule!$F$5:$F$83=A5)*Schedule!$G$5:$G$83))) -> 0 | G5: =E5-F5 -> 0 | H5: =RANK(J5,$J$5:$J$12,0) -> 8 | J5: =C5*10000+G5*100+E5+ROW()/1000 -> 0.005
A6: PJ & Syed | B6: =SUMPRODUCT((Schedule!$C$5:$C$83="Open 4.0")*(Schedule!$D$5:$D$83="League")*ISNUMBER(Schedule!$G$5:$G$83)*ISNUMBER(Schedule!$H$5:$H$83)*((Schedule!$E$5:$E$83=A6)+(Schedule!$F$5:$F$83=A6))) -> 0 | C6: =SUMPRODUCT((Schedule!$C$5:$C$83="Open 4.0")*(Schedule!$D$5:$D$83="League")*ISNUMBER(Schedule!$G$5:$G$83)*ISNUMBER(Schedule!$H$5:$H$83)*(((Schedule!$E$5:$E$83=A6)*(Schedule!$G$5:$G$83>Schedule!$H$5:$H$83))+((Schedule!$F$5:$F$83=A6)*(Schedule!$H$5:$H$83>Schedule!$G$5:$G$83)))) -> 0 | D6: =B6-C6 -> 0 | E6: =SUMPRODUCT((Schedule!$C$5:$C$83="Open 4.0")*(Schedule!$D$5:$D$83="League")*ISNUMBER(Schedule!$G$5:$G$83)*ISNUMBER(Schedule!$H$5:$H$83)*(((Schedule!$E$5:$E$83=A6)*Schedule!$G$5:$G$83)+((Schedule!$F$5:$F$83=A6)*Schedule!$H$5:$H$83))) -> 0 | F6: =SUMPRODUCT((Schedule!$C$5:$C$83="Open 4.0")*(Schedule!$D$5:$D$83="League")*ISNUMBER(Schedule!$G$5:$G$83)*ISNUMBER(Schedule!$H$5:$H$83)*(((Schedule!$E$5:$E$83=A6)*Schedule!$H$5:$H$83)+((Schedule!$F$5:$F$83=A6)*Schedule!$G$5:$G$83))) -> 0 | G6: =E6-F6 -> 0 | H6: =RANK(J6,$J$5:$J$12,0) -> 7 | J6: =C6*10000+G6*100+E6+ROW()/1000 -> 0.006
A7: Rajesh & Uma | B7: =SUMPRODUCT((Schedule!$C$5:$C$83="Open 4.0")*(Schedule!$D$5:$D$83="League")*ISNUMBER(Schedule!$G$5:$G$83)*ISNUMBER(Schedule!$H$5:$H$83)*((Schedule!$E$5:$E$83=A7)+(Schedule!$F$5:$F$83=A7))) -> 0 | C7: =SUMPRODUCT((Schedule!$C$5:$C$83="Open 4.0")*(Schedule!$D$5:$D$83="League")*ISNUMBER(Schedule!$G$5:$G$83)*ISNUMBER(Schedule!$H$5:$H$83)*(((Schedule!$E$5:$E$83=A7)*(Schedule!$G$5:$G$83>Schedule!$H$5:$H$83))+((Schedule!$F$5:$F$83=A7)*(Schedule!$H$5:$H$83>Schedule!$G$5:$G$83)))) -> 0 | D7: =B7-C7 -> 0 | E7: =SUMPRODUCT((Schedule!$C$5:$C$83="Open 4.0")*(Schedule!$D$5:$D$83="League")*ISNUMBER(Schedule!$G$5:$G$83)*ISNUMBER(Schedule!$H$5:$H$83)*(((Schedule!$E$5:$E$83=A7)*Schedule!$G$5:$G$83)+((Schedule!$F$5:$F$83=A7)*Schedule!$H$5:$H$83))) -> 0 | F7: =SUMPRODUCT((Schedule!$C$5:$C$83="Open 4.0")*(Schedule!$D$5:$D$83="League")*ISNUMBER(Schedule!$G$5:$G$83)*ISNUMBER(Schedule!$H$5:$H$83)*(((Schedule!$E$5:$E$83=A7)*Schedule!$H$5:$H$83)+((Schedule!$F$5:$F$83=A7)*Schedule!$G$5:$G$83))) -> 0 | G7: =E7-F7 -> 0 | H7: =RANK(J7,$J$5:$J$12,0) -> 6 | J7: =C7*10000+G7*100+E7+ROW()/1000 -> 0.007
A8: Elango & Arun | B8: =SUMPRODUCT((Schedule!$C$5:$C$83="Open 4.0")*(Schedule!$D$5:$D$83="League")*ISNUMBER(Schedule!$G$5:$G$83)*ISNUMBER(Schedule!$H$5:$H$83)*((Schedule!$E$5:$E$83=A8)+(Schedule!$F$5:$F$83=A8))) -> 0 | C8: =SUMPRODUCT((Schedule!$C$5:$C$83="Open 4.0")*(Schedule!$D$5:$D$83="League")*ISNUMBER(Schedule!$G$5:$G$83)*ISNUMBER(Schedule!$H$5:$H$83)*(((Schedule!$E$5:$E$83=A8)*(Schedule!$G$5:$G$83>Schedule!$H$5:$H$83))+((Schedule!$F$5:$F$83=A8)*(Schedule!$H$5:$H$83>Schedule!$G$5:$G$83)))) -> 0 | D8: =B8-C8 -> 0 | E8: =SUMPRODUCT((Schedule!$C$5:$C$83="Open 4.0")*(Schedule!$D$5:$D$83="League")*ISNUMBER(Schedule!$G$5:$G$83)*ISNUMBER(Schedule!$H$5:$H$83)*(((Schedule!$E$5:$E$83=A8)*Schedule!$G$5:$G$83)+((Schedule!$F$5:$F$83=A8)*Schedule!$H$5:$H$83))) -> 0 | F8: =SUMPRODUCT((Schedule!$C$5:$C$83="Open 4.0")*(Schedule!$D$5:$D$83="League")*ISNUMBER(Schedule!$G$5:$G$83)*ISNUMBER(Schedule!$H$5:$H$83)*(((Schedule!$E$5:$E$83=A8)*Schedule!$H$5:$H$83)+((Schedule!$F$5:$F$83=A8)*Schedule!$G$5:$G$83))) -> 0 | G8: =E8-F8 -> 0 | H8: =RANK(J8,$J$5:$J$12,0) -> 5 | J8: =C8*10000+G8*100+E8+ROW()/1000 -> 0.008
A9: Gifson & Prabakar | B9: =SUMPRODUCT((Schedule!$C$5:$C$83="Open 4.0")*(Schedule!$D$5:$D$83="League")*ISNUMBER(Schedule!$G$5:$G$83)*ISNUMBER(Schedule!$H$5:$H$83)*((Schedule!$E$5:$E$83=A9)+(Schedule!$F$5:$F$83=A9))) -> 0 | C9: =SUMPRODUCT((Schedule!$C$5:$C$83="Open 4.0")*(Schedule!$D$5:$D$83="League")*ISNUMBER(Schedule!$G$5:$G$83)*ISNUMBER(Schedule!$H$5:$H$83)*(((Schedule!$E$5:$E$83=A9)*(Schedule!$G$5:$G$83>Schedule!$H$5:$H$83))+((Schedule!$F$5:$F$83=A9)*(Schedule!$H$5:$H$83>Schedule!$G$5:$G$83)))) -> 0 | D9: =B9-C9 -> 0 | E9: =SUMPRODUCT((Schedule!$C$5:$C$83="Open 4.0")*(Schedule!$D$5:$D$83="League")*ISNUMBER(Schedule!$G$5:$G$83)*ISNUMBER(Schedule!$H$5:$H$83)*(((Schedule!$E$5:$E$83=A9)*Schedule!$G$5:$G$83)+((Schedule!$F$5:$F$83=A9)*Schedule!$H$5:$H$83))) -> 0 | F9: =SUMPRODUCT((Schedule!$C$5:$C$83="Open 4.0")*(Schedule!$D$5:$D$83="League")*ISNUMBER(Schedule!$G$5:$G$83)*ISNUMBER(Schedule!$H$5:$H$83)*(((Schedule!$E$5:$E$83=A9)*Schedule!$H$5:$H$83)+((Schedule!$F$5:$F$83=A9)*Schedule!$G$5:$G$83))) -> 0 | G9: =E9-F9 -> 0 | H9: =RANK(J9,$J$5:$J$12,0) -> 4 | J9: =C9*10000+G9*100+E9+ROW()/1000 -> 0.009
A10: Dwayne & Tony | B10: =SUMPRODUCT((Schedule!$C$5:$C$83="Open 4.0")*(Schedule!$D$5:$D$83="League")*ISNUMBER(Schedule!$G$5:$G$83)*ISNUMBER(Schedule!$H$5:$H$83)*((Schedule!$E$5:$E$83=A10)+(Schedule!$F$5:$F$83=A10))) -> 0 | C10: =SUMPRODUCT((Schedule!$C$5:$C$83="Open 4.0")*(Schedule!$D$5:$D$83="League")*ISNUMBER(Schedule!$G$5:$G$83)*ISNUMBER(Schedule!$H$5:$H$83)*(((Schedule!$E$5:$E$83=A10)*(Schedule!$G$5:$G$83>Schedule!$H$5:$H$83))+((Schedule!$F$5:$F$83=A10)*(Schedule!$H$5:$H$83>Schedule!$G$5:$G$83)))) -> 0 | D10: =B10-C10 -> 0 | E10: =SUMPRODUCT((Schedule!$C$5:$C$83="Open 4.0")*(Schedule!$D$5:$D$83="League")*ISNUMBER(Schedule!$G$5:$G$83)*ISNUMBER(Schedule!$H$5:$H$83)*(((Schedule!$E$5:$E$83=A10)*Schedule!$G$5:$G$83)+((Schedule!$F$5:$F$83=A10)*Schedule!$H$5:$H$83))) -> 0 | F10: =SUMPRODUCT((Schedule!$C$5:$C$83="Open 4.0")*(Schedule!$D$5:$D$83="League")*ISNUMBER(Schedule!$G$5:$G$83)*ISNUMBER(Schedule!$H$5:$H$83)*(((Schedule!$E$5:$E$83=A10)*Schedule!$H$5:$H$83)+((Schedule!$F$5:$F$83=A10)*Schedule!$G$5:$G$83))) -> 0 | G10: =E10-F10 -> 0 | H10: =RANK(J10,$J$5:$J$12,0) -> 3 | J10: =C10*10000+G10*100+E10+ROW()/1000 -> 0.01
A11: Alexis & Chris | B11: =SUMPRODUCT((Schedule!$C$5:$C$83="Open 4.0")*(Schedule!$D$5:$D$83="League")*ISNUMBER(Schedule!$G$5:$G$83)*ISNUMBER(Schedule!$H$5:$H$83)*((Schedule!$E$5:$E$83=A11)+(Schedule!$F$5:$F$83=A11))) -> 0 | C11: =SUMPRODUCT((Schedule!$C$5:$C$83="Open 4.0")*(Schedule!$D$5:$D$83="League")*ISNUMBER(Schedule!$G$5:$G$83)*ISNUMBER(Schedule!$H$5:$H$83)*(((Schedule!$E$5:$E$83=A11)*(Schedule!$G$5:$G$83>Schedule!$H$5:$H$83))+((Schedule!$F$5:$F$83=A11)*(Schedule!$H$5:$H$83>Schedule!$G$5:$G$83)))) -> 0 | D11: =B11-C11 -> 0 | E11: =SUMPRODUCT((Schedule!$C$5:$C$83="Open 4.0")*(Schedule!$D$5:$D$83="League")*ISNUMBER(Schedule!$G$5:$G$83)*ISNUMBER(Schedule!$H$5:$H$83)*(((Schedule!$E$5:$E$83=A11)*Schedule!$G$5:$G$83)+((Schedule!$F$5:$F$83=A11)*Schedule!$H$5:$H$83))) -> 0 | F11: =SUMPRODUCT((Schedule!$C$5:$C$83="Open 4.0")*(Schedule!$D$5:$D$83="League")*ISNUMBER(Schedule!$G$5:$G$83)*ISNUMBER(Schedule!$H$5:$H$83)*(((Schedule!$E$5:$E$83=A11)*Schedule!$H$5:$H$83)+((Schedule!$F$5:$F$83=A11)*Schedule!$G$5:$G$83))) -> 0 | G11: =E11-F11 -> 0 | H11: =RANK(J11,$J$5:$J$12,0) -> 2 | J11: =C11*10000+G11*100+E11+ROW()/1000 -> 0.011
A12: Tim & Scott | B12: =SUMPRODUCT((Schedule!$C$5:$C$83="Open 4.0")*(Schedule!$D$5:$D$83="League")*ISNUMBER(Schedule!$G$5:$G$83)*ISNUMBER(Schedule!$H$5:$H$83)*((Schedule!$E$5:$E$83=A12)+(Schedule!$F$5:$F$83=A12))) -> 0 | C12: =SUMPRODUCT((Schedule!$C$5:$C$83="Open 4.0")*(Schedule!$D$5:$D$83="League")*ISNUMBER(Schedule!$G$5:$G$83)*ISNUMBER(Schedule!$H$5:$H$83)*(((Schedule!$E$5:$E$83=A12)*(Schedule!$G$5:$G$83>Schedule!$H$5:$H$83))+((Schedule!$F$5:$F$83=A12)*(Schedule!$H$5:$H$83>Schedule!$G$5:$G$83)))) -> 0 | D12: =B12-C12 -> 0 | E12: =SUMPRODUCT((Schedule!$C$5:$C$83="Open 4.0")*(Schedule!$D$5:$D$83="League")*ISNUMBER(Schedule!$G$5:$G$83)*ISNUMBER(Schedule!$H$5:$H$83)*(((Schedule!$E$5:$E$83=A12)*Schedule!$G$5:$G$83)+((Schedule!$F$5:$F$83=A12)*Schedule!$H$5:$H$83))) -> 0 | F12: =SUMPRODUCT((Schedule!$C$5:$C$83="Open 4.0")*(Schedule!$D$5:$D$83="League")*ISNUMBER(Schedule!$G$5:$G$83)*ISNUMBER(Schedule!$H$5:$H$83)*(((Schedule!$E$5:$E$83=A12)*Schedule!$H$5:$H$83)+((Schedule!$F$5:$F$83=A12)*Schedule!$G$5:$G$83))) -> 0 | G12: =E12-F12 -> 0 | H12: =RANK(J12,$J$5:$J$12,0) -> 1 | J12: =C12*10000+G12*100+E12+ROW()/1000 -> 0.012
A14: Green rows qualify. Tie on wins, +/- and points for: decide by head-to-head on the Schedule tab.

Sheet Social Doubles
A1: Social Doubles — standings (updates as you type scores on the Schedule tab)
A2: Top 2 play the final. Rank: wins, then +/-, then points for.
A4: Team | B4: Played | C4: Won | D4: Lost | E4: Points for | F4: Points against | G4: +/- | H4: Rank
A5: Ramya & Priya | B5: =SUMPRODUCT((Schedule!$C$5:$C$83="Social Doubles")*(Schedule!$D$5:$D$83="League")*ISNUMBER(Schedule!$G$5:$G$83)*ISNUMBER(Schedule!$H$5:$H$83)*((Schedule!$E$5:$E$83=A5)+(Schedule!$F$5:$F$83=A5))) -> 0 | C5: =SUMPRODUCT((Schedule!$C$5:$C$83="Social Doubles")*(Schedule!$D$5:$D$83="League")*ISNUMBER(Schedule!$G$5:$G$83)*ISNUMBER(Schedule!$H$5:$H$83)*(((Schedule!$E$5:$E$83=A5)*(Schedule!$G$5:$G$83>Schedule!$H$5:$H$83))+((Schedule!$F$5:$F$83=A5)*(Schedule!$H$5:$H$83>Schedule!$G$5:$G$83)))) -> 0 | D5: =B5-C5 -> 0 | E5: =SUMPRODUCT((Schedule!$C$5:$C$83="Social Doubles")*(Schedule!$D$5:$D$83="League")*ISNUMBER(Schedule!$G$5:$G$83)*ISNUMBER(Schedule!$H$5:$H$83)*(((Schedule!$E$5:$E$83=A5)*Schedule!$G$5:$G$83)+((Schedule!$F$5:$F$83=A5)*Schedule!$H$5:$H$83))) -> 0 | F5: =SUMPRODUCT((Schedule!$C$5:$C$83="Social Doubles")*(Schedule!$D$5:$D$83="League")*ISNUMBER(Schedule!$G$5:$G$83)*ISNUMBER(Schedule!$H$5:$H$83)*(((Schedule!$E$5:$E$83=A5)*Schedule!$H$5:$H$83)+((Schedule!$F$5:$F$83=A5)*Schedule!$G$5:$G$83))) -> 0 | G5: =E5-F5 -> 0 | H5: =RANK(J5,$J$5:$J$8,0) -> 4 | J5: =C5*10000+G5*100+E5+ROW()/1000 -> 0.005
A6: Venky & Mohan | B6: =SUMPRODUCT((Schedule!$C$5:$C$83="Social Doubles")*(Schedule!$D$5:$D$83="League")*ISNUMBER(Schedule!$G$5:$G$83)*ISNUMBER(Schedule!$H$5:$H$83)*((Schedule!$E$5:$E$83=A6)+(Schedule!$F$5:$F$83=A6))) -> 0 | C6: =SUMPRODUCT((Schedule!$C$5:$C$83="Social Doubles")*(Schedule!$D$5:$D$83="League")*ISNUMBER(Schedule!$G$5:$G$83)*ISNUMBER(Schedule!$H$5:$H$83)*(((Schedule!$E$5:$E$83=A6)*(Schedule!$G$5:$G$83>Schedule!$H$5:$H$83))+((Schedule!$F$5:$F$83=A6)*(Schedule!$H$5:$H$83>Schedule!$G$5:$G$83)))) -> 0 | D6: =B6-C6 -> 0 | E6: =SUMPRODUCT((Schedule!$C$5:$C$83="Social Doubles")*(Schedule!$D$5:$D$83="League")*ISNUMBER(Schedule!$G$5:$G$83)*ISNUMBER(Schedule!$H$5:$H$83)*(((Schedule!$E$5:$E$83=A6)*Schedule!$G$5:$G$83)+((Schedule!$F$5:$F$83=A6)*Schedule!$H$5:$H$83))) -> 0 | F6: =SUMPRODUCT((Schedule!$C$5:$C$83="Social Doubles")*(Schedule!$D$5:$D$83="League")*ISNUMBER(Schedule!$G$5:$G$83)*ISNUMBER(Schedule!$H$5:$H$83)*(((Schedule!$E$5:$E$83=A6)*Schedule!$H$5:$H$83)+((Schedule!$F$5:$F$83=A6)*Schedule!$G$5:$G$83))) -> 0 | G6: =E6-F6 -> 0 | H6: =RANK(J6,$J$5:$J$8,0) -> 3 | J6: =C6*10000+G6*100+E6+ROW()/1000 -> 0.006
A7: Vasikaran & Sudarson | B7: =SUMPRODUCT((Schedule!$C$5:$C$83="Social Doubles")*(Schedule!$D$5:$D$83="League")*ISNUMBER(Schedule!$G$5:$G$83)*ISNUMBER(Schedule!$H$5:$H$83)*((Schedule!$E$5:$E$83=A7)+(Schedule!$F$5:$F$83=A7))) -> 0 | C7: =SUMPRODUCT((Schedule!$C$5:$C$83="Social Doubles")*(Schedule!$D$5:$D$83="League")*ISNUMBER(Schedule!$G$5:$G$83)*ISNUMBER(Schedule!$H$5:$H$83)*(((Schedule!$E$5:$E$83=A7)*(Schedule!$G$5:$G$83>Schedule!$H$5:$H$83))+((Schedule!$F$5:$F$83=A7)*(Schedule!$H$5:$H$83>Schedule!$G$5:$G$83)))) -> 0 | D7: =B7-C7 -> 0 | E7: =SUMPRODUCT((Schedule!$C$5:$C$83="Social Doubles")*(Schedule!$D$5:$D$83="League")*ISNUMBER(Schedule!$G$5:$G$83)*ISNUMBER(Schedule!$H$5:$H$83)*(((Schedule!$E$5:$E$83=A7)*Schedule!$G$5:$G$83)+((Schedule!$F$5:$F$83=A7)*Schedule!$H$5:$H$83))) -> 0 | F7: =SUMPRODUCT((Schedule!$C$5:$C$83="Social Doubles")*(Schedule!$D$5:$D$83="League")*ISNUMBER(Schedule!$G$5:$G$83)*ISNUMBER(Schedule!$H$5:$H$83)*(((Schedule!$E$5:$E$83=A7)*Schedule!$H$5:$H$83)+((Schedule!$F$5:$F$83=A7)*Schedule!$G$5:$G$83))) -> 0 | G7: =E7-F7 -> 0 | H7: =RANK(J7,$J$5:$J$8,0) -> 2 | J7: =C7*10000+G7*100+E7+ROW()/1000 -> 0.007
A8: Vanith & Yashna | B8: =SUMPRODUCT((Schedule!$C$5:$C$83="Social Doubles")*(Schedule!$D$5:$D$83="League")*ISNUMBER(Schedule!$G$5:$G$83)*ISNUMBER(Schedule!$H$5:$H$83)*((Schedule!$E$5:$E$83=A8)+(Schedule!$F$5:$F$83=A8))) -> 0 | C8: =SUMPRODUCT((Schedule!$C$5:$C$83="Social Doubles")*(Schedule!$D$5:$D$83="League")*ISNUMBER(Schedule!$G$5:$G$83)*ISNUMBER(Schedule!$H$5:$H$83)*(((Schedule!$E$5:$E$83=A8)*(Schedule!$G$5:$G$83>Schedule!$H$5:$H$83))+((Schedule!$F$5:$F$83=A8)*(Schedule!$H$5:$H$83>Schedule!$G$5:$G$83)))) -> 0 | D8: =B8-C8 -> 0 | E8: =SUMPRODUCT((Schedule!$C$5:$C$83="Social Doubles")*(Schedule!$D$5:$D$83="League")*ISNUMBER(Schedule!$G$5:$G$83)*ISNUMBER(Schedule!$H$5:$H$83)*(((Schedule!$E$5:$E$83=A8)*Schedule!$G$5:$G$83)+((Schedule!$F$5:$F$83=A8)*Schedule!$H$5:$H$83))) -> 0 | F8: =SUMPRODUCT((Schedule!$C$5:$C$83="Social Doubles")*(Schedule!$D$5:$D$83="League")*ISNUMBER(Schedule!$G$5:$G$83)*ISNUMBER(Schedule!$H$5:$H$83)*(((Schedule!$E$5:$E$83=A8)*Schedule!$H$5:$H$83)+((Schedule!$F$5:$F$83=A8)*Schedule!$G$5:$G$83))) -> 0 | G8: =E8-F8 -> 0 | H8: =RANK(J8,$J$5:$J$8,0) -> 1 | J8: =C8*10000+G8*100+E8+ROW()/1000 -> 0.008
A10: Green rows qualify. Tie on wins, +/- and points for: decide by head-to-head on the Schedule tab.

Sheet How to use
A1: Offline backup for GTS Pickleball 2026 (Sun Oct 25). The website is the main score system; use this only if it is down.
A2: 1. Schedule tab: type each game's points in the yellow cells. Winner fills in by itself.
A3: 2. Division tabs: standings and rank update automatically from the league scores.
A4: 3. Semis/finals: type the two team names in the yellow Team cells, then the points.
A5: 4. Finals are best of 3: G1, G2 and (only if 1–1) G3.
A6: Rules: League to 11, win by 2, first to 15 wins. Semis to 15, win by 2, first to 21 wins. Finals best of 3 games (each to 11, win by 2, first to 15).
A7: Generated from the approved Plan B v4 (same times and courts as the website).
